[2024-06-11T21:31:47.608-0300] {local_task_job_runner.py:120} INFO - ::group::Pre task execution logs
[2024-06-11T21:31:47.623-0300] {taskinstance.py:2076} INFO - Dependencies all met for dep_context=non-requeueable deps ti=<TaskInstance: data_pipeline.transform_save manual__2024-06-12T00:31:39.986086+00:00 [queued]>
[2024-06-11T21:31:47.630-0300] {taskinstance.py:2076} INFO - Dependencies all met for dep_context=requeueable deps ti=<TaskInstance: data_pipeline.transform_save manual__2024-06-12T00:31:39.986086+00:00 [queued]>
[2024-06-11T21:31:47.631-0300] {taskinstance.py:2306} INFO - Starting attempt 1 of 1
[2024-06-11T21:31:47.641-0300] {taskinstance.py:2330} INFO - Executing <Task(PythonOperator): transform_save> on 2024-06-12 00:31:39.986086+00:00
[2024-06-11T21:31:47.649-0300] {standard_task_runner.py:63} INFO - Started process 29800 to run task
[2024-06-11T21:31:47.651-0300] {standard_task_runner.py:90} INFO - Running: ['airflow', 'tasks', 'run', 'data_pipeline', 'transform_save', 'manual__2024-06-12T00:31:39.986086+00:00', '--job-id', '1752', '--raw', '--subdir', 'DAGS_FOLDER/dag_extracao_daily.py', '--cfg-path', '/tmp/tmpfbvlf80h']
[2024-06-11T21:31:47.652-0300] {standard_task_runner.py:91} INFO - Job 1752: Subtask transform_save
[2024-06-11T21:31:47.684-0300] {task_command.py:426} INFO - Running <TaskInstance: data_pipeline.transform_save manual__2024-06-12T00:31:39.986086+00:00 [running]> on host Pedro-Conrado
[2024-06-11T21:31:47.759-0300] {taskinstance.py:2648} INFO - Exporting env vars: AIRFLOW_CTX_DAG_OWNER='airflow' AIRFLOW_CTX_DAG_ID='data_pipeline' AIRFLOW_CTX_TASK_ID='transform_save' AIRFLOW_CTX_EXECUTION_DATE='2024-06-12T00:31:39.986086+00:00' AIRFLOW_CTX_TRY_NUMBER='1' AIRFLOW_CTX_DAG_RUN_ID='manual__2024-06-12T00:31:39.986086+00:00'
[2024-06-11T21:31:47.760-0300] {taskinstance.py:430} INFO - ::endgroup::
[2024-06-11T21:31:47.768-0300] {logging_mixin.py:188} INFO - /home/pedro/airflow
[2024-06-11T21:31:47.783-0300] {logging_mixin.py:188} INFO - Colunas em orders: Index(['order_id', 'customer_id', 'employee_id', 'order_date', 'required_date',
       'shipped_date', 'ship_via', 'freight', 'ship_name', 'ship_address',
       'ship_city', 'ship_region', 'ship_postal_code', 'ship_country'],
      dtype='object')
[2024-06-11T21:31:47.783-0300] {logging_mixin.py:188} INFO - Colunas em products: Index(['product_id', 'product_name', 'supplier_id', 'category_id',
       'quantity_per_unit', 'unit_price', 'units_in_stock', 'units_on_order',
       'reorder_level', 'discontinued'],
      dtype='object')
[2024-06-11T21:31:47.784-0300] {logging_mixin.py:188} INFO - Colunas em customers: Index(['customer_id', 'company_name', 'contact_name', 'contact_title',
       'address', 'city', 'region', 'postal_code', 'country', 'phone', 'fax'],
      dtype='object')
[2024-06-11T21:31:47.784-0300] {logging_mixin.py:188} INFO - Colunas em order_details: Index(['order_id', 'product_id', 'unit_price', 'quantity', 'discount'], dtype='object')
[2024-06-11T21:31:47.927-0300] {taskinstance.py:441} INFO - ::group::Post task execution logs
[2024-06-11T21:31:47.928-0300] {taskinstance.py:2905} ERROR - Task failed with exception
Traceback (most recent call last):
  File "/home/pedro/.local/lib/python3.10/site-packages/airflow/models/taskinstance.py", line 465, in _execute_task
    result = _execute_callable(context=context, **execute_callable_kwargs)
  File "/home/pedro/.local/lib/python3.10/site-packages/airflow/models/taskinstance.py", line 432, in _execute_callable
    return execute_callable(context=context, **execute_callable_kwargs)
  File "/home/pedro/.local/lib/python3.10/site-packages/airflow/models/baseoperator.py", line 400, in wrapper
    return func(self, *args, **kwargs)
  File "/home/pedro/.local/lib/python3.10/site-packages/airflow/operators/python.py", line 235, in execute
    return_value = self.execute_callable()
  File "/home/pedro/.local/lib/python3.10/site-packages/airflow/operators/python.py", line 252, in execute_callable
    return self.python_callable(*self.op_args, **self.op_kwargs)
  File "/home/pedro/airflow/dags/dag_extracao_daily.py", line 154, in load_to_postgres
    save_db(df)
  File "/home/pedro/airflow/dags/dag_extracao_daily.py", line 112, in save_db
    cursor.execute(insert_stmt, tuple(row))
psycopg2.errors.UndefinedColumn: ERRO:  não existe a coluna "product_id" da relação "merged_table"
LINE 1: INSERT INTO merged_table (product_id,product_name,supplier_i...
                                  ^

[2024-06-11T21:31:47.931-0300] {taskinstance.py:1206} INFO - Marking task as FAILED. dag_id=data_pipeline, task_id=transform_save, run_id=manual__2024-06-12T00:31:39.986086+00:00, execution_date=20240612T003139, start_date=20240612T003147, end_date=20240612T003147
[2024-06-11T21:31:47.940-0300] {standard_task_runner.py:110} ERROR - Failed to execute job 1752 for task transform_save (ERRO:  não existe a coluna "product_id" da relação "merged_table"
LINE 1: INSERT INTO merged_table (product_id,product_name,supplier_i...
                                  ^
; 29800)
[2024-06-11T21:31:47.984-0300] {local_task_job_runner.py:240} INFO - Task exited with return code 1
[2024-06-11T21:31:47.994-0300] {taskinstance.py:3498} INFO - 0 downstream tasks scheduled from follow-on schedule check
[2024-06-11T21:31:47.995-0300] {local_task_job_runner.py:222} INFO - ::endgroup::
