[2024-06-11T21:00:09.895-0300] {local_task_job_runner.py:120} INFO - ::group::Pre task execution logs
[2024-06-11T21:00:09.910-0300] {taskinstance.py:2076} INFO - Dependencies all met for dep_context=non-requeueable deps ti=<TaskInstance: data_pipeline.transform_save scheduled__2024-06-11T00:00:00+00:00 [queued]>
[2024-06-11T21:00:09.915-0300] {taskinstance.py:2076} INFO - Dependencies all met for dep_context=requeueable deps ti=<TaskInstance: data_pipeline.transform_save scheduled__2024-06-11T00:00:00+00:00 [queued]>
[2024-06-11T21:00:09.916-0300] {taskinstance.py:2306} INFO - Starting attempt 1 of 1
[2024-06-11T21:00:09.928-0300] {taskinstance.py:2330} INFO - Executing <Task(PythonOperator): transform_save> on 2024-06-11 00:00:00+00:00
[2024-06-11T21:00:09.930-0300] {standard_task_runner.py:63} INFO - Started process 26181 to run task
[2024-06-11T21:00:09.932-0300] {standard_task_runner.py:90} INFO - Running: ['airflow', 'tasks', 'run', 'data_pipeline', 'transform_save', 'scheduled__2024-06-11T00:00:00+00:00', '--job-id', '1740', '--raw', '--subdir', 'DAGS_FOLDER/dag_extracao_daily.py', '--cfg-path', '/tmp/tmpz7pin_2o']
[2024-06-11T21:00:09.933-0300] {standard_task_runner.py:91} INFO - Job 1740: Subtask transform_save
[2024-06-11T21:00:09.961-0300] {task_command.py:426} INFO - Running <TaskInstance: data_pipeline.transform_save scheduled__2024-06-11T00:00:00+00:00 [running]> on host Pedro-Conrado
[2024-06-11T21:00:10.024-0300] {taskinstance.py:2648} INFO - Exporting env vars: AIRFLOW_CTX_DAG_OWNER='airflow' AIRFLOW_CTX_DAG_ID='data_pipeline' AIRFLOW_CTX_TASK_ID='transform_save' AIRFLOW_CTX_EXECUTION_DATE='2024-06-11T00:00:00+00:00' AIRFLOW_CTX_TRY_NUMBER='1' AIRFLOW_CTX_DAG_RUN_ID='scheduled__2024-06-11T00:00:00+00:00'
[2024-06-11T21:00:10.024-0300] {taskinstance.py:430} INFO - ::endgroup::
[2024-06-11T21:00:10.033-0300] {logging_mixin.py:188} INFO - /home/pedro/airflow
[2024-06-11T21:00:10.044-0300] {logging_mixin.py:188} INFO - Colunas em orders: Index(['order_id', 'customer_id', 'employee_id', 'order_date', 'required_date',
       'shipped_date', 'ship_via', 'freight', 'ship_name', 'ship_address',
       'ship_city', 'ship_region', 'ship_postal_code', 'ship_country'],
      dtype='object')
[2024-06-11T21:00:10.045-0300] {logging_mixin.py:188} INFO - Colunas em products: Index(['product_id', 'product_name', 'supplier_id', 'category_id',
       'quantity_per_unit', 'unit_price', 'units_in_stock', 'units_on_order',
       'reorder_level', 'discontinued'],
      dtype='object')
[2024-06-11T21:00:10.045-0300] {logging_mixin.py:188} INFO - Colunas em customers: Index(['customer_id', 'company_name', 'contact_name', 'contact_title',
       'address', 'city', 'region', 'postal_code', 'country', 'phone', 'fax'],
      dtype='object')
[2024-06-11T21:00:10.050-0300] {logging_mixin.py:188} INFO - Colunas ap처s primeira mesclagem: Index(['order_id', 'customer_id', 'employee_id', 'order_date', 'required_date',
       'shipped_date', 'ship_via', 'freight', 'ship_name', 'ship_address',
       'ship_city', 'ship_region', 'ship_postal_code', 'ship_country',
       'company_name', 'contact_name', 'contact_title', 'address', 'city',
       'region', 'postal_code', 'country', 'phone', 'fax'],
      dtype='object')
[2024-06-11T21:00:10.050-0300] {taskinstance.py:441} INFO - ::group::Post task execution logs
[2024-06-11T21:00:10.051-0300] {taskinstance.py:2905} ERROR - Task failed with exception
Traceback (most recent call last):
  File "/home/pedro/.local/lib/python3.10/site-packages/airflow/models/taskinstance.py", line 465, in _execute_task
    result = _execute_callable(context=context, **execute_callable_kwargs)
  File "/home/pedro/.local/lib/python3.10/site-packages/airflow/models/taskinstance.py", line 432, in _execute_callable
    return execute_callable(context=context, **execute_callable_kwargs)
  File "/home/pedro/.local/lib/python3.10/site-packages/airflow/models/baseoperator.py", line 400, in wrapper
    return func(self, *args, **kwargs)
  File "/home/pedro/.local/lib/python3.10/site-packages/airflow/operators/python.py", line 235, in execute
    return_value = self.execute_callable()
  File "/home/pedro/.local/lib/python3.10/site-packages/airflow/operators/python.py", line 252, in execute_callable
    return self.python_callable(*self.op_args, **self.op_kwargs)
  File "/home/pedro/airflow/dags/dag_extracao_daily.py", line 125, in transform_save
    raise KeyError("Coluna 'product_id' n찾o encontrada em 'products' ou 'merged_data'")
KeyError: "Coluna 'product_id' n찾o encontrada em 'products' ou 'merged_data'"
[2024-06-11T21:00:10.055-0300] {taskinstance.py:1206} INFO - Marking task as FAILED. dag_id=data_pipeline, task_id=transform_save, run_id=scheduled__2024-06-11T00:00:00+00:00, execution_date=20240611T000000, start_date=20240612T000009, end_date=20240612T000010
[2024-06-11T21:00:10.066-0300] {standard_task_runner.py:110} ERROR - Failed to execute job 1740 for task transform_save ("Coluna 'product_id' n찾o encontrada em 'products' ou 'merged_data'"; 26181)
[2024-06-11T21:00:10.106-0300] {local_task_job_runner.py:240} INFO - Task exited with return code 1
[2024-06-11T21:00:10.120-0300] {taskinstance.py:3498} INFO - 0 downstream tasks scheduled from follow-on schedule check
[2024-06-11T21:00:10.121-0300] {local_task_job_runner.py:222} INFO - ::endgroup::
