[2024-06-09T16:28:16.805-0300] {local_task_job_runner.py:120} INFO - ::group::Pre task execution logs
[2024-06-09T16:28:16.816-0300] {taskinstance.py:2076} INFO - Dependencies all met for dep_context=non-requeueable deps ti=<TaskInstance: data_pipeline.transform_save scheduled__2023-01-17T00:00:00+00:00 [queued]>
[2024-06-09T16:28:16.820-0300] {taskinstance.py:2076} INFO - Dependencies all met for dep_context=requeueable deps ti=<TaskInstance: data_pipeline.transform_save scheduled__2023-01-17T00:00:00+00:00 [queued]>
[2024-06-09T16:28:16.820-0300] {taskinstance.py:2306} INFO - Starting attempt 1 of 1
[2024-06-09T16:28:16.830-0300] {taskinstance.py:2330} INFO - Executing <Task(PythonOperator): transform_save> on 2023-01-17 00:00:00+00:00
[2024-06-09T16:28:16.833-0300] {standard_task_runner.py:63} INFO - Started process 5476 to run task
[2024-06-09T16:28:16.835-0300] {standard_task_runner.py:90} INFO - Running: ['airflow', 'tasks', 'run', 'data_pipeline', 'transform_save', 'scheduled__2023-01-17T00:00:00+00:00', '--job-id', '61', '--raw', '--subdir', 'DAGS_FOLDER/dag_extracao_daily.py', '--cfg-path', '/tmp/tmpfuxgq8yr']
[2024-06-09T16:28:16.835-0300] {standard_task_runner.py:91} INFO - Job 61: Subtask transform_save
[2024-06-09T16:28:16.858-0300] {task_command.py:426} INFO - Running <TaskInstance: data_pipeline.transform_save scheduled__2023-01-17T00:00:00+00:00 [running]> on host Pedro-Conrado
[2024-06-09T16:28:16.927-0300] {taskinstance.py:2648} INFO - Exporting env vars: AIRFLOW_CTX_DAG_OWNER='airflow' AIRFLOW_CTX_DAG_ID='data_pipeline' AIRFLOW_CTX_TASK_ID='transform_save' AIRFLOW_CTX_EXECUTION_DATE='2023-01-17T00:00:00+00:00' AIRFLOW_CTX_TRY_NUMBER='1' AIRFLOW_CTX_DAG_RUN_ID='scheduled__2023-01-17T00:00:00+00:00'
[2024-06-09T16:28:16.927-0300] {taskinstance.py:430} INFO - ::endgroup::
[2024-06-09T16:28:16.928-0300] {taskinstance.py:441} INFO - ::group::Post task execution logs
[2024-06-09T16:28:16.928-0300] {taskinstance.py:2905} ERROR - Task failed with exception
Traceback (most recent call last):
  File "/home/pedro/.local/lib/python3.10/site-packages/airflow/models/taskinstance.py", line 465, in _execute_task
    result = _execute_callable(context=context, **execute_callable_kwargs)
  File "/home/pedro/.local/lib/python3.10/site-packages/airflow/models/taskinstance.py", line 432, in _execute_callable
    return execute_callable(context=context, **execute_callable_kwargs)
  File "/home/pedro/.local/lib/python3.10/site-packages/airflow/models/baseoperator.py", line 400, in wrapper
    return func(self, *args, **kwargs)
  File "/home/pedro/.local/lib/python3.10/site-packages/airflow/operators/python.py", line 235, in execute
    return_value = self.execute_callable()
  File "/home/pedro/.local/lib/python3.10/site-packages/airflow/operators/python.py", line 252, in execute_callable
    return self.python_callable(*self.op_args, **self.op_kwargs)
  File "/home/pedro/airflow/dags/dag_extracao_daily.py", line 54, in transform_save
    orders = pd.read_csv('/data/orders/data.csv')
  File "/home/pedro/.local/lib/python3.10/site-packages/pandas/io/parsers/readers.py", line 1026, in read_csv
    return _read(filepath_or_buffer, kwds)
  File "/home/pedro/.local/lib/python3.10/site-packages/pandas/io/parsers/readers.py", line 620, in _read
    parser = TextFileReader(filepath_or_buffer, **kwds)
  File "/home/pedro/.local/lib/python3.10/site-packages/pandas/io/parsers/readers.py", line 1620, in __init__
    self._engine = self._make_engine(f, self.engine)
  File "/home/pedro/.local/lib/python3.10/site-packages/pandas/io/parsers/readers.py", line 1880, in _make_engine
    self.handles = get_handle(
  File "/home/pedro/.local/lib/python3.10/site-packages/pandas/io/common.py", line 873, in get_handle
    handle = open(
FileNotFoundError: [Errno 2] No such file or directory: '/data/orders/data.csv'
[2024-06-09T16:28:16.931-0300] {taskinstance.py:1206} INFO - Marking task as FAILED. dag_id=data_pipeline, task_id=transform_save, run_id=scheduled__2023-01-17T00:00:00+00:00, execution_date=20230117T000000, start_date=20240609T192816, end_date=20240609T192816
[2024-06-09T16:28:16.940-0300] {standard_task_runner.py:110} ERROR - Failed to execute job 61 for task transform_save ([Errno 2] No such file or directory: '/data/orders/data.csv'; 5476)
[2024-06-09T16:28:16.967-0300] {local_task_job_runner.py:240} INFO - Task exited with return code 1
[2024-06-09T16:28:16.985-0300] {taskinstance.py:3498} INFO - 0 downstream tasks scheduled from follow-on schedule check
[2024-06-09T16:28:16.985-0300] {local_task_job_runner.py:222} INFO - ::endgroup::
